Workbook

Sheet 780 a pred
A1: product_id | B1: cluster_2018 | C1: Tons Prom Oct-Dic19 | D1: #Meses completos Ene-Dic'18 | E1: %Ton/Cluster | F1: Seleccionado | H1: Etiquetas de fila | I1: Cuenta de product_id | K1: Tons Prom Oct-Dic19 | M1: Ranking por Ton
A2: 20002 | B2: 3 | C2: 1496.8074 | D2: 12 | E2: =$C2/SUMIF($B$2:$B$781,B2,$C$2:$C$781) -> 0.45196106 | F2: =IF(AND(OR(B2=0,B2=3,B2=7),D2=12),"Sí","") -> Sí | H2: 0 | I2: 456 | J2: =I2/I$11 -> 0.58461538 | K2: =SUMIF($B$2:$B$781,H2,$C$2:$C$781) -> 15263.19 | L2: =K2/K$11 -> 0.49665076 | M2: 1ro
A3: 20001 | B3: 7 | C3: 1487.8555 | D3: 12 | E3: =$C3/SUMIF($B$2:$B$781,B3,$C$2:$C$781) -> 0.22459249 | F3: =IF(AND(OR(B3=0,B3=3,B3=7),D3=12),"Sí","") -> Sí | H3: 1 | I3: 14 | J3: =I3/I$11 -> 0.017948718 | K3: =SUMIF($B$2:$B$781,H3,$C$2:$C$781) -> 438.70251 | L3: =K3/K$11 -> 0.014274993 | M3: 6to
A4: 20003 | B4: 3 | C4: 974.05389 | D4: 12 | E4: =$C4/SUMIF($B$2:$B$781,B4,$C$2:$C$781) -> 0.29411561 | F4: =IF(AND(OR(B4=0,B4=3,B4=7),D4=12),"Sí","") -> Sí | H4: 2 | I4: 66 | J4: =I4/I$11 -> 0.084615385 | K4: =SUMIF($B$2:$B$781,H4,$C$2:$C$781) -> 2473.6054 | L4: =K4/K$11 -> 0.08048894 | M4: 4to
A5: 20004 | B5: 7 | C5: 808.84614 | D5: 12 | E5: =$C5/SUMIF($B$2:$B$781,B5,$C$2:$C$781) -> 0.12209571 | F5: =IF(AND(OR(B5=0,B5=3,B5=7),D5=12),"Sí","") -> Sí | H5: 3 | I5: 13 | J5: =I5/I$11 -> 0.016666667 | K5: =SUMIF($B$2:$B$781,H5,$C$2:$C$781) -> 3311.8062 | L5: =K5/K$11 -> 0.10776325 | M5: 3ro
A6: 20005 | B6: 0 | C6: 732.31297 | D6: 12 | E6: =$C6/SUMIF($B$2:$B$781,B6,$C$2:$C$781) -> 0.047979023 | F6: =IF(AND(OR(B6=0,B6=3,B6=7),D6=12),"Sí","") -> Sí | H6: 4 | I6: 19 | J6: =I6/I$11 -> 0.024358974 | K6: =SUMIF($B$2:$B$781,H6,$C$2:$C$781) -> 86.444613 | L6: =K6/K$11 -> 0.0028128315 | M6: 8vo
A7: 20032 | B7: Serie 2018 incompleta ==> promediar | C7: 728.55481 | D7: 0 | E7: =$C7/SUMIF($B$2:$B$781,B7,$C$2:$C$781) -> 0.31630127 | F7: =IF(AND(OR(B7=0,B7=3,B7=7),D7=12),"Sí","") | H7: 5 | I7: 15 | J7: =I7/I$11 -> 0.019230769 | K7: =SUMIF($B$2:$B$781,H7,$C$2:$C$781) -> 229.25647 | L7: =K7/K$11 -> 0.0074598033 | M7: 7mo
A8: 20009 | B8: 2 | C8: 587.6926 | D8: 12 | E8: =$C8/SUMIF($B$2:$B$781,B8,$C$2:$C$781) -> 0.23758543 | F8: =IF(AND(OR(B8=0,B8=3,B8=7),D8=12),"Sí","") | H8: 6 | I8: 1 | J8: =I8/I$11 -> 0.0012820513 | K8: =SUMIF($B$2:$B$781,H8,$C$2:$C$781) -> 1.18779 | L8: =K8/K$11 -> 3.8649639e-05 | M8: 9no
A9: 20006 | B9: 0 | C9: 448.39093 | D9: 12 | E9: =$C9/SUMIF($B$2:$B$781,B9,$C$2:$C$781) -> 0.029377274 | F9: =IF(AND(OR(B9=0,B9=3,B9=7),D9=12),"Sí","") -> Sí | H9: 7 | I9: 72 | J9: =I9/I$11 -> 0.092307692 | K9: =SUMIF($B$2:$B$781,H9,$C$2:$C$781) -> 6624.6894 | L9: =K9/K$11 -> 0.21556155 | M9: 2do
A10: 20010 | B10: 7 | C10: 426.46245 | D10: 12 | E10: =$C10/SUMIF($B$2:$B$781,B10,$C$2:$C$781) -> 0.064374708 | F10: =IF(AND(OR(B10=0,B10=3,B10=7),D10=12),"Sí","") -> Sí | H10: Serie 2018 incompleta ==> promediar | I10: 124 | J10: =I10/I$11 -> 0.15897436 | K10: =SUMIF($B$2:$B$781,H10,$C$2:$C$781) -> 2303.3572 | L10: =K10/K$11 -> 0.074949213 | M10: 5to
A11: 20014 | B11: 0 | C11: 399.9632 | D11: 12 | E11: =$C11/SUMIF($B$2:$B$781,B11,$C$2:$C$781) -> 0.02620443 | F11: =IF(AND(OR(B11=0,B11=3,B11=7),D11=12),"Sí","") -> Sí | H11: Total general | I11: 780 | J11: =I11/I$11 -> 1 | K11: =SUM(K2:K10) -> 30732.24 | L11: =K11/K$11 -> 1
A12: 20007 | B12: 0 | C12: 397.88076 | D12: 12 | E12: =$C12/SUMIF($B$2:$B$781,B12,$C$2:$C$781) -> 0.026067994 | F12: =IF(AND(OR(B12=0,B12=3,B12=7),D12=12),"Sí","") -> Sí
A13: 20019 | B13: 7 | C13: 394.18423 | D13: 12 | E13: =$C13/SUMIF($B$2:$B$781,B13,$C$2:$C$781) -> 0.059502296 | F13: =IF(AND(OR(B13=0,B13=3,B13=7),D13=12),"Sí","") -> Sí
A14: 20013 | B14: 0 | C14: 393.86256 | D14: 12 | E14: =$C14/SUMIF($B$2:$B$781,B14,$C$2:$C$781) -> 0.025804733 | F14: =IF(AND(OR(B14=0,B14=3,B14=7),D14=12),"Sí","") -> Sí
A15: 20011 | B15: 0 | C15: 370.07334 | D15: 12 | E15: =$C15/SUMIF($B$2:$B$781,B15,$C$2:$C$781) -> 0.024246133 | F15: =IF(AND(OR(B15=0,B15=3,B15=7),D15=12),"Sí","") -> Sí
A16: 20015 | B16: 3 | C16: 364.1017 | D16: 12 | E16: =$C16/SUMIF($B$2:$B$781,B16,$C$2:$C$781) -> 0.10994052 | F16: =IF(AND(OR(B16=0,B16=3,B16=7),D16=12),"Sí","") -> Sí
A17: 20008 | B17: 0 | C17: 348.21295 | D17: 12 | E17: =$C17/SUMIF($B$2:$B$781,B17,$C$2:$C$781) -> 0.022813903 | F17: =IF(AND(OR(B17=0,B17=3,B17=7),D17=12),"Sí","") -> Sí
A18: 20026 | B18: 0 | C18: 306.54185 | D18: 12 | E18: =$C18/SUMIF($B$2:$B$781,B18,$C$2:$C$781) -> 0.020083734 | F18: =IF(AND(OR(B18=0,B18=3,B18=7),D18=12),"Sí","") -> Sí
A19: 20016 | B19: 0 | C19: 281.34834 | D19: 12 | E19: =$C19/SUMIF($B$2:$B$781,B19,$C$2:$C$781) -> 0.018433128 | F19: =IF(AND(OR(B19=0,B19=3,B19=7),D19=12),"Sí","") -> Sí
A20: 20023 | B20: 0 | C20: 281.27645 | D20: 12 | E20: =$C20/SUMIF($B$2:$B$781,B20,$C$2:$C$781) -> 0.018428418 | F20: =IF(AND(OR(B20=0,B20=3,B20=7),D20=12),"Sí","") -> Sí
A21: 20020 | B21: 0 | C21: 275.25971 | D21: 12 | E21: =$C21/SUMIF($B$2:$B$781,B21,$C$2:$C$781) -> 0.018034218 | F21: =IF(AND(OR(B21=0,B21=3,B21=7),D21=12),"Sí","") -> Sí
A22: 20127 | B22: Serie 2018 incompleta ==> promediar | C22: 273.6486 | D22: 0 | E22: =$C22/SUMIF($B$2:$B$781,B22,$C$2:$C$781) -> 0.11880424 | F22: =IF(AND(OR(B22=0,B22=3,B22=7),D22=12),"Sí","")
A23: 20012 | B23: 0 | C23: 270.84656 | D23: 12 | E23: =$C23/SUMIF($B$2:$B$781,B23,$C$2:$C$781) -> 0.017745082 | F23: =IF(AND(OR(B23=0,B23=3,B23=7),D23=12),"Sí","") -> Sí
A24: 20017 | B24: 0 | C24: 245.29899 | D24: 12 | E24: =$C24/SUMIF($B$2:$B$781,B24,$C$2:$C$781) -> 0.016071279 | F24: =IF(AND(OR(B24=0,B24=3,B24=7),D24=12),"Sí","") -> Sí
A25: 20021 | B25: 7 | C25: 244.76821 | D25: 12 | E25: =$C25/SUMIF($B$2:$B$781,B25,$C$2:$C$781) -> 0.036947876 | F25: =IF(AND(OR(B25=0,B25=3,B25=7),D25=12),"Sí","") -> Sí
A26: 20022 | B26: 1 | C26: 241.02622 | D26: 12 | E26: =$C26/SUMIF($B$2:$B$781,B26,$C$2:$C$781) -> 0.54940697 | F26: =IF(AND(OR(B26=0,B26=3,B26=7),D26=12),"Sí","")
A27: 20018 | B27: 0 | C27: 224.56842 | D27: 12 | E27: =$C27/SUMIF($B$2:$B$781,B27,$C$2:$C$781) -> 0.014713072 | F27: =IF(AND(OR(B27=0,B27=3,B27=7),D27=12),"Sí","") -> Sí
A28: 20027 | B28: 2 | C28: 216.33502 | D28: 12 | E28: =$C28/SUMIF($B$2:$B$781,B28,$C$2:$C$781) -> 0.087457369 | F28: =IF(AND(OR(B28=0,B28=3,B28=7),D28=12),"Sí","")
A29: 20024 | B29: 0 | C29: 210.25368 | D29: 12 | E29: =$C29/SUMIF($B$2:$B$781,B29,$C$2:$C$781) -> 0.013775212 | F29: =IF(AND(OR(B29=0,B29=3,B29=7),D29=12),"Sí","") -> Sí
A30: 20025 | B30: 0 | C30: 210.06258 | D30: 12 | E30: =$C30/SUMIF($B$2:$B$781,B30,$C$2:$C$781) -> 0.013762691 | F30: =IF(AND(OR(B30=0,B30=3,B30=7),D30=12),"Sí","") -> Sí
A31: 20085 | B31: 2 | C31: 209.58541 | D31: 3 | E31: =$C31/SUMIF($B$2:$B$781,B31,$C$2:$C$781) -> 0.084728716 | F31: =IF(AND(OR(B31=0,B31=3,B31=7),D31=12),"Sí","")
A32: 20031 | B32: 0 | C32: 201.13182 | D32: 12 | E32: =$C32/SUMIF($B$2:$B$781,B32,$C$2:$C$781) -> 0.013177574 | F32: =IF(AND(OR(B32=0,B32=3,B32=7),D32=12),"Sí","") -> Sí
A33: 20089 | B33: 2 | C33: 190.61176 | D33: 5 | E33: =$C33/SUMIF($B$2:$B$781,B33,$C$2:$C$781) -> 0.07705827 | F33: =IF(AND(OR(B33=0,B33=3,B33=7),D33=12),"Sí","")
A34: 20042 | B34: 0 | C34: 181.32716 | D34: 12 | E34: =$C34/SUMIF($B$2:$B$781,B34,$C$2:$C$781) -> 0.01188003 | F34: =IF(AND(OR(B34=0,B34=3,B34=7),D34=12),"Sí","") -> Sí
... A68: 20150 | B68: 7 | C68: 107.41561 | D68: 9 | E68: =$C68/SUMIF($B$2:$B$781,B68,$C$2:$C$781) -> 0.016214437 | F68: =IF(AND(OR(B68=0,B68=3,B68=7),D68=12),"Sí","")
A69: 20210 | B69: Serie 2018 incompleta ==> promediar | C69: 106.97632 | D69: 0 | E69: =$C69/SUMIF($B$2:$B$781,B69,$C$2:$C$781) -> 0.046443652 | F69: =IF(AND(OR(B69=0,B69=3,B69=7),D69=12),"Sí","")
A70: 20056 | B70: 7 | C70: 106.61924 | D70: 12 | E70: =$C70/SUMIF($B$2:$B$781,B70,$C$2:$C$781) -> 0.016094225 | F70: =IF(AND(OR(B70=0,B70=3,B70=7),D70=12),"Sí","") -> Sí
A71: 20094 | B71: 0 | C71: 104.60008 | D71: 12 | E71: =$C71/SUMIF($B$2:$B$781,B71,$C$2:$C$781) -> 0.0068530938 | F71: =IF(AND(OR(B71=0,B71=3,B71=7),D71=12),"Sí","") -> Sí
A72: 20174 | B72: Serie 2018 incompleta ==> promediar | C72: 102.49379 | D72: 0 | E72: =$C72/SUMIF($B$2:$B$781,B72,$C$2:$C$781) -> 0.044497566 | F72: =IF(AND(OR(B72=0,B72=3,B72=7),D72=12),"Sí","")
A73: 20081 | B73: 0 | C73: 100.9554 | D73: 12 | E73: =$C73/SUMIF($B$2:$B$781,B73,$C$2:$C$781) -> 0.0066143052 | F73: =IF(AND(OR(B73=0,B73=3,B73=7),D73=12),"Sí","") -> Sí
...

Sheet 33 magicos
A1: Product_ID | B1: Cluster DTW | C1: Tons Prom Oct-Dic19 | E1: Etiquetas de fila | F1: Cuenta de Product_ID | H1: Tons Prom Oct-Dic19
A2: 20001 | B2: =VLOOKUP(A2,'780 a pred'!$A$2:$B$781,2,0) -> 7 | C2: 1487.8555 | E2: 0 | F2: 20 | G2: =F2/F$6 -> 0.60606061 | H2: =SUMIF($B$2:$B$34,E2,$C$2:$C$34) -> 2936.3772 | I2: =H2/H$6 -> 0.32617886
A3: 20002 | B3: =VLOOKUP(A3,'780 a pred'!$A$2:$B$781,2,0) -> 3 | C3: 1496.8074 | E3: 3 | F3: 3 | G3: =F3/F$6 -> 0.090909091 | H3: =SUMIF($B$2:$B$34,E3,$C$2:$C$34) -> 2651.2459 | I3: =H3/H$6 -> 0.29450589
A4: 20003 | B4: =VLOOKUP(A4,'780 a pred'!$A$2:$B$781,2,0) -> 3 | C4: 974.05389 | E4: 5 | F4: 1 | G4: =F4/F$6 -> 0.03030303 | H4: =SUMIF($B$2:$B$34,E4,$C$2:$C$34) -> 37.03873 | I4: =H4/H$6 -> 0.0041143389
A5: 20006 | B5: =VLOOKUP(A5,'780 a pred'!$A$2:$B$781,2,0) -> 0 | C5: 448.39093 | E5: 7 | F5: 9 | G5: =F5/F$6 -> 0.27272727 | H5: =SUMIF($B$2:$B$34,E5,$C$2:$C$34) -> 3377.6909 | I5: =H5/H$6 -> 0.37520091
A6: 20008 | B6: =VLOOKUP(A6,'780 a pred'!$A$2:$B$781,2,0) -> 0 | C6: 348.21295 | E6: Total general | F6: 33 | G6: =F6/F$6 -> 1 | H6: =SUM(H2:H5) -> 9002.3527 | I6: =H6/H$6 -> 1
A7: 20010 | B7: =VLOOKUP(A7,'780 a pred'!$A$2:$B$781,2,0) -> 7 | C7: 426.46245
A8: 20011 | B8: =VLOOKUP(A8,'780 a pred'!$A$2:$B$781,2,0) -> 0 | C8: 370.07334
A9: 20017 | B9: =VLOOKUP(A9,'780 a pred'!$A$2:$B$781,2,0) -> 0 | C9: 245.29899
A10: 20018 | B10: =VLOOKUP(A10,'780 a pred'!$A$2:$B$781,2,0) -> 0 | C10: 224.56842
A11: 20019 | B11: =VLOOKUP(A11,'780 a pred'!$A$2:$B$781,2,0) -> 7 | C11: 394.18423
A12: 20021 | B12: =VLOOKUP(A12,'780 a pred'!$A$2:$B$781,2,0) -> 7 | C12: 244.76821
A13: 20026 | B13: =VLOOKUP(A13,'780 a pred'!$A$2:$B$781,2,0) -> 0 | C13: 306.54185
A14: 20028 | B14: =VLOOKUP(A14,'780 a pred'!$A$2:$B$781,2,0) -> 7 | C14: 171.26382
A15: 20035 | B15: =VLOOKUP(A15,'780 a pred'!$A$2:$B$781,2,0) -> 7 | C15: 168.89315
A16: 20039 | B16: =VLOOKUP(A16,'780 a pred'!$A$2:$B$781,2,0) -> 0 | C16: 148.75227
A17: 20042 | B17: =VLOOKUP(A17,'780 a pred'!$A$2:$B$781,2,0) -> 0 | C17: 181.32716
A18: 20044 | B18: =VLOOKUP(A18,'780 a pred'!$A$2:$B$781,2,0) -> 0 | C18: 164.60371
... A34: 20838 | B34: =VLOOKUP(A34,'780 a pred'!$A$2:$B$781,2,0) -> 0 | C34: 1.7495067
